#VRML_SIM R2023a utf8

EXTERNPROTO "https://raw.githubusercontent.com/cyberbotics/webots/R2023a/projects/objects/floors/protos/RectangleArena.proto"
EXTERNPROTO "https://raw.githubusercontent.com/cyberbotics/webots/R2023a/projects/objects/backgrounds/protos/TexturedBackground.proto"
EXTERNPROTO "https://raw.githubusercontent.com/cyberbotics/webots/R2023a/projects/objects/backgrounds/protos/TexturedBackgroundLight.proto"
EXTERNPROTO "https://raw.githubusercontent.com/cyberbotics/webots/R2023a/projects/objects/apartment_structure/protos/Wall.proto"
EXTERNPROTO "https://raw.githubusercontent.com/cyberbotics/webots/R2023a/projects/appearances/protos/Roughcast.proto"

WorldInfo {
}
Viewpoint {
  orientation -0.7017823864907536 -0.002833388499485341 0.7123857479771429 3.147348965343849
  position 5.584585067364131 6.0330441501740735 33.737083254643935
  follow "robot"
}
TexturedBackground {
}
TexturedBackgroundLight {
}
RectangleArena {
  translation 6.25 6.25 0
  rotation 0 1 0 0
  floorSize 12.5 12.5
}
Wall {
  translation 7.72047 5.15593 -5.75984e-13
  rotation 0 1 0 0
  name "wall(7)"
  size 1 0.15 0.15
  appearance Roughcast {
    colorOverride 0 0 0
    textureTransform TextureTransform {
      scale 2.4 1
    }
  }
}
Wall {
  translation 3.24783 6.35703 -5.76872e-13
  rotation 0 1 0 0
  name "wall(31)"
  size 1 0.15 0.15
  appearance Roughcast {
    colorOverride 0 0 0
    textureTransform TextureTransform {
      scale 2.4 1
    }
  }
}
Wall {
  translation 4.23661 10.4865 -5.57332e-13
  rotation 0 1 0 0
  name "wall(33)"
  size 1 1 0.15
  appearance Roughcast {
    colorOverride 0 0 0
    textureTransform TextureTransform {
      scale 2.4 1
    }
  }
}
Wall {
  translation 7.26154 3.75835 -5.97301e-13
  rotation 0 1 0 0
  name "wall(57)"
  size 1 1 0.15
  appearance Roughcast {
    colorOverride 0 0 0
    textureTransform TextureTransform {
      scale 2.4 1
    }
  }
}
Wall {
  translation 8.97516 5.42078 -5.93748e-13
  rotation 0 1 0 0
  name "wall(54)"
  size 1 0.15 0.15
  appearance Roughcast {
    colorOverride 0 0 0
    textureTransform TextureTransform {
      scale 2.4 1
    }
  }
}
Wall {
  translation 0.641018 1.01854 -7.10543e-15
  rotation 0 0 1 -1.5707953071795862
  name "wall(5)"
  size 1 0.15 0.15
  appearance Roughcast {
    colorOverride 0 0 0
    textureTransform TextureTransform {
      scale 2.4 1
    }
  }
}
Wall {
  translation 6.83521 5.55669 -4.7409e-21
  rotation 0 0 -0.9999999999999999 1.5707953071795862
  name "wall(8)"
  size 1 0.15 0.15
  appearance Roughcast {
    colorOverride 0 0 0
    textureTransform TextureTransform {
      scale 2.4 1
    }
  }
}
DEF robot Robot {
  translation 0.152489 0.048485 -0.000186017
  rotation -0.016288710348377113 0.015433017828566783 -0.9997482182409178 1.51519849025885
  children [
    InertialUnit {
    }
    GPS {
    }
    DEF body Transform {
      translation 0 0 0.0415
      children [
        Shape {
          appearance PBRAppearance {
            baseColor 0 0 1
            roughness 1
            metalness 0
          }
          geometry Cylinder {
            height 0.08
            radius 0.045
          }
        }
      ]
    }
    HingeJoint {
      jointParameters HingeJointParameters {
        position 198.65987199871375
        anchor 0.045 0 0.025
      }
      device [
        RotationalMotor {
          name "motor_1"
        }
        PositionSensor {
          name "ps_1"
        }
      ]
      endPoint Solid {
        translation 0.045 0 0.025
        rotation -0.6822482633863923 0.26422593570487335 -0.6817051870179192 2.6245545204324654
        children [
          DEF wheel Shape {
            appearance PBRAppearance {
              baseColor 1 0 0
              roughness 1
              metalness 0
            }
            geometry Cylinder {
              height 0.01
              radius 0.025
            }
          }
        ]
        boundingObject USE wheel
        physics DEF wheel_physics Physics {
        }
      }
    }
    HingeJoint {
      jointParameters HingeJointParameters {
        position 216.5536404007148
        anchor -0.045 0 0.025
      }
      device [
        RotationalMotor {
          name "motor_2"
        }
        PositionSensor {
          name "ps_2"
        }
      ]
      endPoint Solid {
        translation -0.045 0 0.025
        rotation 0.7053152806616491 0.07650082377160262 0.7047538427191763 2.988767258624893
        children [
          USE wheel
        ]
        name "solid(1)"
        boundingObject USE wheel
        physics USE wheel_physics
      }
    }
    Solid {
      translation 0.015 -0.045 0.07
      children [
        DEF eye Shape {
          appearance PBRAppearance {
            baseColor 1 0 0
            roughness 1
            metalness 0
          }
          geometry Box {
            size 0.005 0.005 0.005
          }
        }
      ]
      name "solid(2)"
    }
    Solid {
      translation -0.015 -0.045 0.07
      children [
        USE eye
      ]
      name "solid(3)"
    }
  ]
  boundingObject USE body
  physics Physics {
  }
  controller "robot_controller"
}
Wall {
  translation 9.86455 11.2501 -2.66454e-15
  rotation 0 0 1 -1.5707953071795862
  name "wall(12)"
  size 1 0.15 0.15
  appearance Roughcast {
    colorOverride 0 0 0
    textureTransform TextureTransform {
      scale 2.4 1
    }
  }
}
Wall {
  translation 10.6218 10.4982 -2.66454e-15
  rotation 0 0 -0.9999999999999999 1.5707953071795862
  name "wall(58)"
  size 1 0.15 0.15
  appearance Roughcast {
    colorOverride 0 0 0
    textureTransform TextureTransform {
      scale 2.4 1
    }
  }
}
Wall {
  translation 6.08174 12.0197 -2.66454e-15
  rotation 0 0 1 -1.5707953071795862
  name "wall(32)"
  size 1 0.15 0.15
  appearance Roughcast {
    colorOverride 0 0 0
    textureTransform TextureTransform {
      scale 2.4 1
    }
  }
}
Wall {
  translation 1.85644 3.54091 -2.23821e-13
  rotation 0 0 1 -1.5707953071795862
  name "wall(22)"
  size 2 0.15 0.15
  appearance Roughcast {
    colorOverride 0 0 0
    textureTransform TextureTransform {
      scale 2.4 1
    }
  }
}
Wall {
  translation 3.6205 7.01225 -2.93099e-13
  rotation 0 0 -0.9999999999999999 1.5707953071795862
  name "wall(53)"
  size 1 0.15 0.15
  appearance Roughcast {
    colorOverride 0 0 0
    textureTransform TextureTransform {
      scale 2.4 1
    }
  }
}
Wall {
  translation 10.3616 11.9861 2.66453e-15
  rotation 0 0 1 -1.5707953071795862
  name "wall(26)"
  size 1 0.15 0.15
  appearance Roughcast {
    colorOverride 0 0 0
    textureTransform TextureTransform {
      scale 2.4 1
    }
  }
}
Wall {
  translation 1.85956 1.01502 -2.66454e-15
  rotation 0 0 1 -1.5707953071795862
  name "wall(27)"
  size 1 0.15 0.15
  appearance Roughcast {
    colorOverride 0 0 0
    textureTransform TextureTransform {
      scale 2.4 1
    }
  }
}
Wall {
  translation 7.11392 0.482489 1.59872e-14
  rotation 0 0 1 -1.5707953071795862
  name "wall(28)"
  size 1 0.15 0.15
  appearance Roughcast {
    colorOverride 0 0 0
    textureTransform TextureTransform {
      scale 2.4 1
    }
  }
}
Wall {
  translation 11.6266 2.0062 -1.77636e-15
  rotation 0 0 1 -1.5707953071795862
  name "wall(29)"
  size 1 0.15 0.15
  appearance Roughcast {
    colorOverride 0 0 0
    textureTransform TextureTransform {
      scale 2.4 1
    }
  }
}
Wall {
  translation 7.87492 1.25942 -2.66454e-15
  rotation 0 0 1 -1.5707953071795862
  name "wall(43)"
  size 1 0.15 0.15
  appearance Roughcast {
    colorOverride 0 0 0
    textureTransform TextureTransform {
      scale 2.4 1
    }
  }
}
Wall {
  translation 1.85984 7.75305 -3.55272e-15
  rotation 0 0 1 -1.5707953071795862
  name "wall(23)"
  size 1 0.15 0.15
  appearance Roughcast {
    colorOverride 0 0 0
    textureTransform TextureTransform {
      scale 2.4 1
    }
  }
}
Wall {
  translation 5.63015 11.4464 5.77316e-14
  rotation 0 0 -0.9999999999999999 1.5707953071795862
  name "wall(55)"
  size 1 0.15 0.15
  appearance Roughcast {
    colorOverride 0 0 0
    textureTransform TextureTransform {
      scale 2.4 1
    }
  }
}
Wall {
  translation 2.57978 6.0021 -1.86518e-14
  rotation 0 0 1 -1.5707953071795862
  name "wall(25)"
  size 1 0.15 0.15
  appearance Roughcast {
    colorOverride 0 0 0
    textureTransform TextureTransform {
      scale 2.4 1
    }
  }
}
Wall {
  translation 1.12684 6.50393 2.66453e-15
  rotation 0 0 1 -1.5707953071795862
  name "wall(61)"
  size 1 0.15 0.15
  appearance Roughcast {
    colorOverride 0 0 0
    textureTransform TextureTransform {
      scale 2.4 1
    }
  }
}
Wall {
  translation 7.57848 6.783 -2.66454e-15
  rotation 0 0 1 -1.5707953071795862
  name "wall(10)"
  size 1 0.15 0.15
  appearance Roughcast {
    colorOverride 0 0 0
    textureTransform TextureTransform {
      scale 2.4 1
    }
  }
}
Wall {
  translation 1.38345 9.98924 2.74447e-13
  rotation 0 0 1 -1.5707953071795862
  name "wall(50)"
  size 2 0.15 0.15
  appearance Roughcast {
    colorOverride 0 0 0
    textureTransform TextureTransform {
      scale 2.4 1
    }
  }
}
Wall {
  translation 3.87509 4.52709 -1.9984e-14
  rotation 0 0 1 -1.5707953071795862
  name "wall(51)"
  size 1 0.15 0.15
  appearance Roughcast {
    colorOverride 0 0 0
    textureTransform TextureTransform {
      scale 2.4 1
    }
  }
}
Wall {
  translation 2.88349 10.5035 -1.9984e-14
  rotation 0 0 1 -1.5707953071795862
  name "wall(65)"
  size 1 0.15 0.15
  appearance Roughcast {
    colorOverride 0 0 0
    textureTransform TextureTransform {
      scale 2.4 1
    }
  }
}
Wall {
  translation 9.87831 5.3102 -3.86358e-14
  rotation 0 0 1 -1.5707953071795862
  name "wall(4)"
  size 1.5 0.15 0.15
  appearance Roughcast {
    colorOverride 0 0 0
    textureTransform TextureTransform {
      scale 2.4 1
    }
  }
}
Wall {
  translation 11.6134 4.25226 -3.86358e-14
  rotation 0 0 1 -1.5707953071795862
  name "wall(46)"
  size 1.5 0.15 0.15
  appearance Roughcast {
    colorOverride 0 0 0
    textureTransform TextureTransform {
      scale 2.4 1
    }
  }
}
Wall {
  translation 9.62072 7.99493 4.24994e-13
  rotation 0 0 1 -1.5707953071795862
  name "wall(14)"
  size 1.5 0.15 0.15
  appearance Roughcast {
    colorOverride 0 0 0
    textureTransform TextureTransform {
      scale 2.4 1
    }
  }
}
Wall {
  translation 7.87152 9.5062 4.30323e-13
  rotation 0 0 1 -1.5707953071795862
  name "wall(24)"
  size 1.5 0.15 0.15
  appearance Roughcast {
    colorOverride 0 0 0
    textureTransform TextureTransform {
      scale 2.4 1
    }
  }
}
Wall {
  translation 2.0959 11.7373 4.30323e-13
  rotation 0 0 1 -1.5707953071795862
  name "wall(64)"
  size 1.5 0.15 0.15
  appearance Roughcast {
    colorOverride 0 0 0
    textureTransform TextureTransform {
      scale 2.4 1
    }
  }
}
Wall {
  translation 4.86152 8.48689 -1.02138e-14
  rotation 0 0 1 -1.5707953071795862
  name "wall(47)"
  size 1.5 0.15 0.15
  appearance Roughcast {
    colorOverride 0 0 0
    textureTransform TextureTransform {
      scale 2.4 1
    }
  }
}
Wall {
  translation 5.35954 5.28114 4.2677e-13
  rotation 0 0 1 -1.5707953071795862
  name "wall(41)"
  size 1.5 0.15 0.15
  appearance Roughcast {
    colorOverride 0 0 0
    textureTransform TextureTransform {
      scale 2.4 1
    }
  }
}
Wall {
  translation 2.87605 7.9805 4.15224e-13
  rotation 0 0 1 -1.5707953071795862
  name "wall(35)"
  size 1.5 0.15 0.15
  appearance Roughcast {
    colorOverride 0 0 0
    textureTransform TextureTransform {
      scale 2.4 1
    }
  }
}
Wall {
  translation 6.85 11.2846 4.23217e-13
  rotation 0 0 1 -1.5707953071795862
  name "wall(56)"
  size 1.5 0.15 0.15
  appearance Roughcast {
    colorOverride 0 0 0
    textureTransform TextureTransform {
      scale 2.4 1
    }
  }
}
Wall {
  translation 4.11699 0.742843 4.2677e-13
  rotation 0 0 1 -1.5707953071795862
  name "wall(37)"
  size 1.5 0.15 0.15
  appearance Roughcast {
    colorOverride 0 0 0
    textureTransform TextureTransform {
      scale 2.4 1
    }
  }
}
Wall {
  translation 9.10907 3.55062 4.30323e-13
  rotation 0 0 1 -1.5707953071795862
  name "wall(20)"
  size 1.5 0.15 0.15
  appearance Roughcast {
    colorOverride 0 0 0
    textureTransform TextureTransform {
      scale 2.4 1
    }
  }
}
Wall {
  translation 4.86218 2.50775 4.30323e-13
  rotation 0 0 1 -1.5707953071795862
  name "wall(39)"
  size 1.5 0.15 0.15
  appearance Roughcast {
    colorOverride 0 0 0
    textureTransform TextureTransform {
      scale 2.4 1
    }
  }
}
Wall {
  translation 11.3757 11.2587 3.68597e-14
  rotation 0 0 1 -1.5707953071795862
  name "wall(19)"
  size 1.5 0.15 0.15
  appearance Roughcast {
    colorOverride 0 0 0
    textureTransform TextureTransform {
      scale 2.4 1
    }
  }
}
Wall {
  translation 3.09039 2.55802 -3.10863e-15
  rotation 0 0 1 -1.5707953071795862
  name "wall(15)"
  size 1.5 0.15 0.15
  appearance Roughcast {
    colorOverride 0 0 0
    textureTransform TextureTransform {
      scale 2.4 1
    }
  }
}
Wall {
  translation 6.10056 2.52937 -4.7409e-21
  rotation 0 0 1 -1.5707953071795862
  name "wall(2)"
  size 5 0.15 0.15
  appearance Roughcast {
    colorOverride 0 0 0
    textureTransform TextureTransform {
      scale 2.4 1
    }
  }
}
Wall {
  translation 6.08248 8.257 -4.7409e-21
  rotation 0 0 1 -1.5707953071795862
  name "wall(6)"
  size 5 0.15 0.15
  appearance Roughcast {
    colorOverride 0 0 0
    textureTransform TextureTransform {
      scale 2.4 1
    }
  }
}
Wall {
  translation 11.8763 7.75295 -4.7409e-21
  rotation 0 0 1 -1.5707953071795862
  name "wall(59)"
  size 3 0.15 0.15
  appearance Roughcast {
    colorOverride 0 0 0
    textureTransform TextureTransform {
      scale 2.4 1
    }
  }
}
Wall {
  translation 11.9867 11.3695 -1.96731e-13
  rotation 0 1 0 0
  name "wall(1)"
  size 1 0.15 0.15
  appearance Roughcast {
    colorOverride 0 0 0
    textureTransform TextureTransform {
      scale 2.4 1
    }
  }
}
Wall {
  translation 1.26317 0.877249 -1.79856e-13
  rotation 0 1 0 0
  name "wall(18)"
  size 1 0.15 0.15
  appearance Roughcast {
    colorOverride 0 0 0
    textureTransform TextureTransform {
      scale 2.4 1
    }
  }
}
Wall {
  translation 7.22984 6.17287 -4.44089e-16
  rotation 0 1 0 0
  name "wall(9)"
  size 1 0.15 0.15
  appearance Roughcast {
    colorOverride 0 0 0
    textureTransform TextureTransform {
      scale 2.4 1
    }
  }
}
Wall {
  translation 9.2537 4.41554 6.26165e-14
  rotation 0 1 0 0
  name "wall(3)"
  size 1.5 0.15 0.15
  appearance Roughcast {
    colorOverride 0 0 0
    textureTransform TextureTransform {
      scale 2.4 1
    }
  }
}
Wall {
  translation 10.504 8.12128 7.86038e-14
  rotation 0 1 0 0
  name "wall(13)"
  size 1.5 0.15 0.15
  appearance Roughcast {
    colorOverride 0 0 0
    textureTransform TextureTransform {
      scale 2.4 1
    }
  }
}
Wall {
  translation 4.01453 8.38658 3.89466e-13
  rotation 0 1 0 0
  name "wall(49)"
  size 1.5 0.15 0.15
  appearance Roughcast {
    colorOverride 0 0 0
    textureTransform TextureTransform {
      scale 2.4 1
    }
  }
}
Wall {
  translation 4.97251 3.38499 6.9722e-14
  rotation 0 1 0 0
  name "wall(40)"
  size 1.5 0.15 0.15
  appearance Roughcast {
    colorOverride 0 0 0
    textureTransform TextureTransform {
      scale 2.4 1
    }
  }
}
Wall {
  translation 1.75545 4.63884 7.23865e-14
  rotation 0 1 0 0
  name "wall(34)"
  size 1.5 0.15 0.15
  appearance Roughcast {
    colorOverride 0 0 0
    textureTransform TextureTransform {
      scale 2.4 1
    }
  }
}
Wall {
  translation 1.23433 7.13187 7.23865e-14
  rotation 0 1 0 0
  name "wall(60)"
  size 1.5 0.15 0.15
  appearance Roughcast {
    colorOverride 0 0 0
    textureTransform TextureTransform {
      scale 2.4 1
    }
  }
}
Wall {
  translation 11.7422 2.64132 6.26166e-14
  rotation 0 1 0 0
  name "wall(21)"
  size 1.5 0.15 0.15
  appearance Roughcast {
    colorOverride 0 0 0
    textureTransform TextureTransform {
      scale 2.4 1
    }
  }
}
Wall {
  translation 9.20471 2.66806 6.26166e-14
  rotation 0 1 0 0
  name "wall(45)"
  size 1.5 0.15 0.15
  appearance Roughcast {
    colorOverride 0 0 0
    textureTransform TextureTransform {
      scale 2.4 1
    }
  }
}
Wall {
  translation 2.45436 1.66866 5.19584e-14
  rotation 0 1 0 0
  name "wall(17)"
  size 1.5 0.15 0.15
  appearance Roughcast {
    colorOverride 0 0 0
    textureTransform TextureTransform {
      scale 2.4 1
    }
  }
}
Wall {
  translation 8.69164 1.64975 5.19584e-14
  rotation 0 1 0 0
  name "wall(30)"
  size 1.5 0.15 0.15
  appearance Roughcast {
    colorOverride 0 0 0
    textureTransform TextureTransform {
      scale 2.4 1
    }
  }
}
Wall {
  translation 11.2506 1.37436 5.19584e-14
  rotation 0 1 0 0
  name "wall(44)"
  size 1.5 0.15 0.15
  appearance Roughcast {
    colorOverride 0 0 0
    textureTransform TextureTransform {
      scale 2.4 1
    }
  }
}
Wall {
  translation 4.48001 1.64674 5.19584e-14
  rotation 0 1 0 0
  name "wall(38)"
  size 1.5 0.15 0.15
  appearance Roughcast {
    colorOverride 0 0 0
    textureTransform TextureTransform {
      scale 2.4 1
    }
  }
}
Wall {
  translation 7.48519 12.1233 4.29879e-13
  rotation 0 1 0 0
  name "wall(16)"
  size 1.5 0.15 0.15
  appearance Roughcast {
    colorOverride 0 0 0
    textureTransform TextureTransform {
      scale 2.4 1
    }
  }
}
Wall {
  translation 2.21063 9.87202 7.16317e-13
  rotation 0 1 0 0
  name "wall(52)"
  size 1.5 0.15 0.15
  appearance Roughcast {
    colorOverride 0 0 0
    textureTransform TextureTransform {
      scale 2.4 1
    }
  }
}
Wall {
  translation 9.47205 8.87634 4.20109e-13
  rotation 0 1 0 0
  name "wall(36)"
  size 1.5 0.15 0.15
  appearance Roughcast {
    colorOverride 0 0 0
    textureTransform TextureTransform {
      scale 2.4 1
    }
  }
}
Wall {
  translation 8.48575 10.3702 4.10783e-13
  rotation 0 1 0 0
  name "wall(62)"
  size 1.5 0.15 0.15
  appearance Roughcast {
    colorOverride 0 0 0
    textureTransform TextureTransform {
      scale 2.4 1
    }
  }
}
Wall {
  translation 2.94858 11.9017 3.78809e-13
  rotation 0 1 0 0
  name "wall(63)"
  size 1.5 0.15 0.15
  appearance Roughcast {
    colorOverride 0 0 0
    textureTransform TextureTransform {
      scale 2.4 1
    }
  }
}
Wall {
  translation 4.94104 9.36528 -1.93178e-13
  rotation 0 1 0 0
  name "wall(48)"
  size 1.5 0.15 0.15
  appearance Roughcast {
    colorOverride 0 0 0
    textureTransform TextureTransform {
      scale 2.4 1
    }
  }
}
Wall {
  translation 4.93698 6.14623 4.21441e-13
  rotation 0 1 0 0
  name "wall(42)"
  size 1.5 0.15 0.15
  appearance Roughcast {
    colorOverride 0 0 0
    textureTransform TextureTransform {
      scale 2.4 1
    }
  }
}
Wall {
  translation 8.22457 7.40181 5.0182e-14
  rotation 0 1 0 0
  name "wall(11)"
  size 1.5 0.15 0.15
  appearance Roughcast {
    colorOverride 0 0 0
    textureTransform TextureTransform {
      scale 2.4 1
    }
  }
}
